Workbook

Sheet Center_Cities
A1: City | B1: State | C1: LAT | D1: LON
A2: Birmingham | B2: AL | C2: 33.518661 | D2: -86.810325
A3: Anchorage | B3: AK | C3: 61.217041 | D3: -149.89082
A4: Phoenix | B4: AZ | C4: 33.455476 | D4: -112.07028
A5: Tucson | B5: AZ | C5: 32.220172 | D5: -110.97405
A6: Los Angeles | B6: CA | C6: 34.044218 | D6: -118.24418
A7: Oakland | B7: CA | C7: 37.804418 | D7: -122.2712
A8: San Diego | B8: CA | C8: 32.714678 | D8: -117.16242
A9: San Francisco | B9: CA | C9: 37.779607 | D9: -122.41765
A10: Denver | B10: CO | C10: 39.74788 | D10: -105.00004
A11: Washington DC | B11: DC | C11: 38.905295 | D11: -77.038399
A12: Jacksonville | B12: FL | C12: 30.327864 | D12: -81.654782
A13: Miami | B13: FL | C13: 25.77539 | D13: -80.192692
... A47: Milwaukee | B47: WI | C47: 43.038972 | D47: -87.903837

Sheet Cities
A1: City | B1: State | C1: State_Adj | D1: LAT | E1: LON
A2: ='Raw List'!J8 -> Birmingham | B2: ='Raw List'!M8 -> AL | C2: =SUBSTITUTE(B2," ","") -> AL | D2: ='Raw List'!N8 -> 33.57 | E2: =-'Raw List'!O8 -> -86.75
A3: ='Raw List'!J28 -> Anchorage | B3: ='Raw List'!M28 -> AK | C3: =SUBSTITUTE(B3," ","") -> AK | D3: ='Raw List'!N28 -> 61.17 | E3: =-'Raw List'!O28 -> -150.02
A4: ='Raw List'!J74 -> Juneau | B4: ='Raw List'!M74 -> AK | C4: =SUBSTITUTE(B4," ","") -> AK | D4: ='Raw List'!N74 -> 58.37 | E4: =-'Raw List'!O74 -> -134.58
A5: ='Raw List'!J146 -> Phoenix | B5: ='Raw List'!M146 -> AZ | C5: =SUBSTITUTE(B5," ","") -> AZ | D5: ='Raw List'!N146 -> 33.43 | E5: =-'Raw List'!O146 -> -112.02
A6: ='Raw List'!J152 -> Tucson | B6: ='Raw List'!M152 -> AZ | C6: =SUBSTITUTE(B6," ","") -> AZ | D6: ='Raw List'!N152 -> 32.12 | E6: =-'Raw List'!O152 -> -110.93
A7: ='Raw List'!J170 -> Little Rock | B7: ='Raw List'!M170 -> AR | C7: =SUBSTITUTE(B7," ","") -> AR | D7: ='Raw List'!N170 -> 35.22 | E7: =-'Raw List'!O170 -> -92.38
A8: ='Raw List'!J191 -> Burbank | B8: ='Raw List'!M191 -> CA | C8: =SUBSTITUTE(B8," ","") -> CA | D8: ='Raw List'!N191 -> 34.2 | E8: =-'Raw List'!O191 -> -118.37
A9: ='Raw List'!J221 -> Long Beach | B9: ='Raw List'!M221 -> CA | C9: =SUBSTITUTE(B9," ","") -> CA | D9: ='Raw List'!N221 -> 33.82 | E9: =-'Raw List'!O221 -> -118.15
A10: ='Raw List'!J223 -> Los Angeles | B10: ='Raw List'!M223 -> CA | C10: =SUBSTITUTE(B10," ","") -> CA | D10: ='Raw List'!N223 -> 33.93 | E10: =-'Raw List'!O223 -> -118.4
A11: ='Raw List'!J242 -> Oakland | B11: ='Raw List'!M242 -> CA | C11: =SUBSTITUTE(B11," ","") -> CA | D11: ='Raw List'!N242 -> 37.73 | E11: =-'Raw List'!O242 -> -122.22
A12: ='Raw List'!J264 -> San Diego | B12: ='Raw List'!M264 -> CA | C12: =SUBSTITUTE(B12," ","") -> CA | D12: ='Raw List'!N264 -> 32.82 | E12: =-'Raw List'!O264 -> -117.13
A13: ='Raw List'!J269 -> San Francisco | B13: ='Raw List'!M269 -> CA | C13: =SUBSTITUTE(B13," ","") -> CA | D13: ='Raw List'!N269 -> 37.75 | E13: =-'Raw List'!O269 -> -122.68
A14: ='Raw List'!J271 -> San Jose | B14: ='Raw List'!M271 -> CA | C14: =SUBSTITUTE(B14," ","") -> CA | D14: ='Raw List'!N271 -> 37.37 | E14: =-'Raw List'!O271 -> -121.92
A15: ='Raw List'!J311 -> Denver | B15: ='Raw List'!M311 -> CO | C15: =SUBSTITUTE(B15," ","") -> CO | D15: ='Raw List'!N311 -> 39.75 | E15: =-'Raw List'!O311 -> -104.87
A16: ='Raw List'!J338 -> Bridgeport | B16: ='Raw List'!M338 -> CT | C16: =SUBSTITUTE(B16," ","") -> CT | D16: ='Raw List'!N338 -> 41.17 | E16: =-'Raw List'!O338 -> -73.13
A17: ='Raw List'!J341 -> Hartford | B17: ='Raw List'!M341 -> CT | C17: =SUBSTITUTE(B17," ","") -> CT | D17: ='Raw List'!N341 -> 41.73 | E17: =-'Raw List'!O341 -> -72.65
A18: ='Raw List'!J357 -> Washington | B18: ='Raw List'!M357 -> DC | C18: =SUBSTITUTE(B18," ","") -> DC | D18: ='Raw List'!N357 -> 38.85 | E18: =-'Raw List'!O357 -> -77.04
A19: ='Raw List'!J374 -> Ft Lauderdale | B19: ='Raw List'!M374 -> FL | C19: =SUBSTITUTE(B19," ","") -> FL | D19: ='Raw List'!N374 -> 26.07 | E19: =-'Raw List'!O374 -> -80.15
A20: ='Raw List'!J381 -> Jacksonville | B20: ='Raw List'!M381 -> FL | C20: =SUBSTITUTE(B20," ","") -> FL | D20: ='Raw List'!N381 -> 30.23 | E20: =-'Raw List'!O381 -> -81.68
A21: Miami | B21: ='Raw List'!M389 -> FL | C21: =SUBSTITUTE(B21," ","") -> FL | D21: ='Raw List'!N389 -> 25.82 | E21: =-'Raw List'!O389 -> -80.28
A22: ='Raw List'!J394 -> Orlando | B22: ='Raw List'!M394 -> FL | C22: =SUBSTITUTE(B22," ","") -> FL | D22: ='Raw List'!N394 -> 28.43 | E22: =-'Raw List'!O394 -> -81.32
A23: Tampa | B23: ='Raw List'!M405 -> FL | C23: =SUBSTITUTE(B23," ","") -> FL | D23: ='Raw List'!N405 -> 27.97 | E23: =-'Raw List'!O405 -> -82.53
A24: ='Raw List'!J418 -> Atlanta | B24: ='Raw List'!M418 -> GA | C24: =SUBSTITUTE(B24," ","") -> GA | D24: ='Raw List'!N418 -> 33.65 | E24: =-'Raw List'!O418 -> -84.42
A25: Honolulu | B25: ='Raw List'!M445 -> HI | C25: =SUBSTITUTE(B25," ","") -> HI | D25: ='Raw List'!N445 -> 21.35 | E25: =-'Raw List'!O445 -> -157.93
A26: ='Raw List'!J460 -> Boise | B26: ='Raw List'!M460 -> ID | C26: =SUBSTITUTE(B26," ","") -> ID | D26: ='Raw List'!N460 -> 43.57 | E26: =-'Raw List'!O460 -> -116.22
A27: ='Raw List'!J492 -> Chicago | B27: ='Raw List'!M492 -> IL | C27: =SUBSTITUTE(B27," ","") -> IL | D27: ='Raw List'!N492 -> 41.9 | E27: =-'Raw List'!O492 -> -87.65
A28: ='Raw List'!J529 -> Indianapolis | B28: ='Raw List'!M529 -> IN | C28: =SUBSTITUTE(B28," ","") -> IN | D28: ='Raw List'!N529 -> 39.73 | E28: =-'Raw List'!O529 -> -86.27
A29: ='Raw List'!J539 -> Des Moines | B29: ='Raw List'!M539 -> IA | C29: =SUBSTITUTE(B29," ","") -> IA | D29: ='Raw List'!N539 -> 41.53 | E29: =-'Raw List'!O539 -> -93.65
A30: ='Raw List'!J586 -> Louisville | B30: ='Raw List'!M586 -> KY | C30: =SUBSTITUTE(B30," ","") -> KY | D30: ='Raw List'!N586 -> 38.18 | E30: =-'Raw List'!O586 -> -85.73
A31: ='Raw List'!J595 -> Baton Rouge | B31: ='Raw List'!M595 -> LA | C31: =SUBSTITUTE(B31," ","") -> LA | D31: ='Raw List'!N595 -> 30.53 | E31: =-'Raw List'!O595 -> -91.15
A32: ='Raw List'!J614 -> New Orleans | B32: ='Raw List'!M614 -> LA | C32: =SUBSTITUTE(B32," ","") -> LA | D32: ='Raw List'!N614 -> 29.98 | E32: =-'Raw List'!O614 -> -90.25
A33: ='Raw List'!J633 -> Portland | B33: ='Raw List'!M633 -> ME | C33: =SUBSTITUTE(B33," ","") -> ME | D33: ='Raw List'!N633 -> 43.65 | E33: =-'Raw List'!O633 -> -70.32
A34: ='Raw List'!J643 -> Baltimore | B34: ='Raw List'!M643 -> MD | C34: =SUBSTITUTE(B34," ","") -> MD | D34: ='Raw List'!N643 -> 39.33 | E34: =-'Raw List'!O643 -> -76.42
A35: ='Raw List'!J655 -> Boston | B35: ='Raw List'!M655 -> MA | C35: =SUBSTITUTE(B35," ","") -> MA | D35: ='Raw List'!N655 -> 42.37 | E35: =-'Raw List'!O655 -> -71.03
A36: ='Raw List'!J674 -> Alpena | B36: ='Raw List'!M674 -> MI | C36: =SUBSTITUTE(B36," ","") -> MI | D36: ='Raw List'!N674 -> 45.07 | E36: =-'Raw List'!O674 -> -83.57
A37: ='Raw List'!J675 -> Ann Arbor | B37: ='Raw List'!M675 -> MI | C37: =SUBSTITUTE(B37," ","") -> MI | D37: ='Raw List'!N675 -> 42.22 | E37: =-'Raw List'!O675 -> -83.75
A38: ='Raw List'!J681 -> Detroit | B38: ='Raw List'!M681 -> MI | C38: =SUBSTITUTE(B38," ","") -> MI | D38: ='Raw List'!N681 -> 42.42 | E38: =-'Raw List'!O681 -> -83.02
A39: ='Raw List'!J728 -> Minneapolis | B39: ='Raw List'!M728 -> MN | C39: =SUBSTITUTE(B39," ","") -> MN | D39: ='Raw List'!N728 -> 44.88 | E39: =-'Raw List'!O728 -> -93.22
A40: ='Raw List'!J765 -> Kansas City | B40: ='Raw List'!M765 -> MO | C40: =SUBSTITUTE(B40," ","") -> MO | D40: ='Raw List'!N765 -> 39.32 | E40: =-'Raw List'!O765 -> -94.72
...

Sheet Raw List
A1: ID | B1: LAT | C1: LON | D1: Location
A2: https://www.w3.org/2003/01/geo/test/ustowns/latlong.htm
A3: Alabama
J5: City | K5: State | M5: State Adj. | N5: LAT | O5: LON
A6: [ANB] | B6: 33.58 | C6: 85.85 | D6: Anniston,AL | H6: Anniston,AL | J6: =LEFT(H6,LEN(H6)-5) -> Anniston | K6: =RIGHT(H6,4) -> AL | L6: =LEFT(K6,LEN(K6)-1) -> AL | M6: =SUBSTITUTE(L6,",","") -> AL | N6: =B6 -> 33.58 | O6: =C6 -> 85.85
A7: [AUO] | B7: 32.67 | C7: 85.44 | D7: Auburn,AL | H7: Auburn,AL | J7: =LEFT(H7,LEN(H7)-5) -> Auburn | K7: =RIGHT(H7,4) -> AL | L7: =LEFT(K7,LEN(K7)-1) -> AL | M7: =SUBSTITUTE(L7,",","") -> AL | N7: =B7 -> 32.67 | O7: =C7 -> 85.44
A8: [BHM] | B8: 33.57 | C8: 86.75 | D8: Birmingham,AL | H8: Birmingham,AL | J8: =LEFT(H8,LEN(H8)-5) -> Birmingham | K8: =RIGHT(H8,4) -> AL | L8: =LEFT(K8,LEN(K8)-1) -> AL | M8: =SUBSTITUTE(L8,",","") -> AL | N8: =B8 -> 33.57 | O8: =C8 -> 86.75
A9: [CKL] | B9: 32.9 | C9: 87.25 | D9: Centreville,AL | H9: Centreville,AL | J9: =LEFT(H9,LEN(H9)-5) -> Centreville | K9: =RIGHT(H9,4) -> AL | L9: =LEFT(K9,LEN(K9)-1) -> AL | M9: =SUBSTITUTE(L9,",","") -> AL | N9: =B9 -> 32.9 | O9: =C9 -> 87.25
A10: [DHN] | B10: 31.32 | C10: 85.45 | D10: Dothan,AL | H10: Dothan,AL | J10: =LEFT(H10,LEN(H10)-5) -> Dothan | K10: =RIGHT(H10,4) -> AL | L10: =LEFT(K10,LEN(K10)-1) -> AL | M10: =SUBSTITUTE(L10,",","") -> AL | N10: =B10 -> 31.32 | O10: =C10 -> 85.45
A11: [OZR] | B11: 31.28 | C11: 85.72 | D11: Fort | E11: Rucker,AL | H11: Fort Rucker,AL | J11: =LEFT(H11,LEN(H11)-5) -> Fort Rucke | K11: =RIGHT(H11,4) -> ,AL | L11: =LEFT(K11,LEN(K11)-1) -> ,AL | M11: =SUBSTITUTE(L11,",","") -> AL | N11: =B11 -> 31.28 | O11: =C11 -> 85.72
A12: [GAD] | B12: 33.97 | C12: 86.09 | D12: Gadsden,AL | H12: Gadsden,AL | J12: =LEFT(H12,LEN(H12)-5) -> Gadsden | K12: =RIGHT(H12,4) -> AL | L12: =LEFT(K12,LEN(K12)-1) -> AL | M12: =SUBSTITUTE(L12,",","") -> AL | N12: =B12 -> 33.97 | O12: =C12 -> 86.09
A13: [HSV] | B13: 34.65 | C13: 86.77 | D13: Huntsville,AL | H13: Huntsville,AL | J13: =LEFT(H13,LEN(H13)-5) -> Huntsville | K13: =RIGHT(H13,4) -> AL | L13: =LEFT(K13,LEN(K13)-1) -> AL | M13: =SUBSTITUTE(L13,",","") -> AL | N13: =B13 -> 34.65 | O13: =C13 -> 86.77
A14: [MXF] | B14: 32.38 | C14: 86.37 | D14: Maxwell | E14: AFB,AL | H14: Maxwell AFB,AL | J14: =LEFT(H14,LEN(H14)-5) -> Maxwell AF | K14: =RIGHT(H14,4) -> ,AL | L14: =LEFT(K14,LEN(K14)-1) -> ,AL | M14: =SUBSTITUTE(L14,",","") -> AL | N14: =B14 -> 32.38 | O14: =C14 -> 86.37
A15: [MOB] | B15: 30.68 | C15: 88.25 | D15: Mobile,AL | H15: Mobile,AL | J15: =LEFT(H15,LEN(H15)-5) -> Mobile | K15: =RIGHT(H15,4) -> AL | L15: =LEFT(K15,LEN(K15)-1) -> AL | M15: =SUBSTITUTE(L15,",","") -> AL | N15: =B15 -> 30.68 | O15: =C15 -> 88.25
A16: [BFM] | B16: 30.63 | C16: 88.07 | D16: Mobile | E16: Aeros,AL | H16: Mobile Aeros,AL | J16: =LEFT(H16,LEN(H16)-5) -> Mobile Aero | K16: =RIGHT(H16,4) -> ,AL | L16: =LEFT(K16,LEN(K16)-1) -> ,AL | M16: =SUBSTITUTE(L16,",","") -> AL | N16: =B16 -> 30.63 | O16: =C16 -> 88.07
A17: [MGM] | B17: 32.3 | C17: 86.4 | D17: Montgomery,AL | H17: Montgomery,AL | J17: =LEFT(H17,LEN(H17)-5) -> Montgomery | K17: =RIGHT(H17,4) -> AL | L17: =LEFT(K17,LEN(K17)-1) -> AL | M17: =SUBSTITUTE(L17,",","") -> AL | N17: =B17 -> 32.3 | O17: =C17 -> 86.4
A18: [MSL] | B18: 34.75 | C18: 87.62 | D18: Muscle | E18: Shoal,AL | H18: Muscle Shoal,AL | J18: =LEFT(H18,LEN(H18)-5) -> Muscle Shoa | K18: =RIGHT(H18,4) -> ,AL | L18: =LEFT(K18,LEN(K18)-1) -> ,AL | M18: =SUBSTITUTE(L18,",","") -> AL | N18: =B18 -> 34.75 | O18: =C18 -> 87.62
A19: [SEM] | B19: 32.34 | C19: 86.99 | D19: Selma,AL | H19: Selma,AL | J19: =LEFT(H19,LEN(H19)-5) -> Selma | K19: =RIGHT(H19,4) -> AL | L19: =LEFT(K19,LEN(K19)-1) -> AL | M19: =SUBSTITUTE(L19,",","") -> AL | N19: =B19 -> 32.34 | O19: =C19 -> 86.99
A20: [TOI] | B20: 31.87 | C20: 86.02 | D20: Troy,AL | H20: Troy,AL | J20: =LEFT(H20,LEN(H20)-5) -> Troy | K20: =RIGHT(H20,4) -> AL | L20: =LEFT(K20,LEN(K20)-1) -> AL | M20: =SUBSTITUTE(L20,",","") -> AL | N20: =B20 -> 31.87 | O20: =C20 -> 86.02
A21: [TCL] | B21: 33.23 | C21: 87.62 | D21: Tuscaloosa,AL | H21: Tuscaloosa,AL | J21: =LEFT(H21,LEN(H21)-5) -> Tuscaloosa | K21: =RIGHT(H21,4) -> AL | L21: =LEFT(K21,LEN(K21)-1) -> AL | M21: =SUBSTITUTE(L21,",","") -> AL | N21: =B21 -> 33.23 | O21: =C21 -> 87.62
A23: Alaska
A26: [ADK] | B26: 51.88 | C26: 176.65 | D26: Adak,AK | H26: Adak,AK | J26: =LEFT(H26,LEN(H26)-5) -> Adak | K26: =RIGHT(H26,4) -> AK | L26: =LEFT(K26,LEN(K26)-1) -> AK | M26: =SUBSTITUTE(L26,",","") -> AK | N26: =B26 -> 51.88 | O26: =C26 -> 176.65
A27: [Z60] | B27: 67.1 | C27: 157.85 | D27: Ambler,AK | H27: Ambler,AK | J27: =LEFT(H27,LEN(H27)-5) -> Ambler | K27: =RIGHT(H27,4) -> AK | L27: =LEFT(K27,LEN(K27)-1) -> AK | M27: =SUBSTITUTE(L27,",","") -> AK | N27: =B27 -> 67.1 | O27: =C27 -> 157.85
A28: [ANC] | B28: 61.17 | C28: 150.02 | D28: Anchorage,AK | H28: Anchorage,AK | J28: =LEFT(H28,LEN(H28)-5) -> Anchorage | K28: =RIGHT(H28,4) -> AK | L28: =LEFT(K28,LEN(K28)-1) -> AK | M28: =SUBSTITUTE(L28,",","") -> AK | N28: =B28 -> 61.17 | O28: =C28 -> 150.02
A29: [MRI] | B29: 61.22 | C29: 149.85 | D29: Anchorage,AK | H29: Anchorage,AK | J29: =LEFT(H29,LEN(H29)-5) -> Anchorage | K29: =RIGHT(H29,4) -> AK | L29: =LEFT(K29,LEN(K29)-1) -> AK | M29: =SUBSTITUTE(L29,",","") -> AK | N29: =B29 -> 61.22 | O29: =C29 -> 149.85
A30: [AGN] | B30: 57.83 | C30: 134.97 | D30: Angoon,AK | H30: Angoon,AK | J30: =LEFT(H30,LEN(H30)-5) -> Angoon | K30: =RIGHT(H30,4) -> AK | L30: =LEFT(K30,LEN(K30)-1) -> AK | M30: =SUBSTITUTE(L30,",","") -> AK | N30: =B30 -> 57.83 | O30: =C30 -> 134.97
A31: [ANI] | B31: 61.58 | C31: 159.53 | D31: Aniak,AK | H31: Aniak,AK | J31: =LEFT(H31,LEN(H31)-5) -> Aniak | K31: =RIGHT(H31,4) -> AK | L31: =LEFT(K31,LEN(K31)-1) -> AK | M31: =SUBSTITUTE(L31,",","") -> AK | N31: =B31 -> 61.58 | O31: =C31 -> 159.53
A32: [ANN] | B32: 55.03 | C32: 131.57 | D32: Annette | E32: Isl,AK | H32: Annette Isl,AK | J32: =LEFT(H32,LEN(H32)-5) -> Annette Is | K32: =RIGHT(H32,4) -> ,AK | L32: =LEFT(K32,LEN(K32)-1) -> ,AK | M32: =SUBSTITUTE(L32,",","") -> AK | N32: =B32 -> 55.03 | O32: =C32 -> 131.57
A33: [ATU] | B33: 53.5 | C33: 173.3 | D33: Attu,AK | H33: Attu,AK | J33: =LEFT(H33,LEN(H33)-5) -> Attu | K33: =RIGHT(H33,4) -> AK | L33: =LEFT(K33,LEN(K33)-1) -> AK | M33: =SUBSTITUTE(L33,",","") -> AK | N33: =B33 -> 53.5 | O33: =C33 -> 173.3
A34: [BRW] | B34: 71.3 | C34: 156.78 | D34: Barrow,AK | H34: Barrow,AK | J34: =LEFT(H34,LEN(H34)-5) -> Barrow | K34: =RIGHT(H34,4) -> AK | L34: =LEFT(K34,LEN(K34)-1) -> AK | M34: =SUBSTITUTE(L34,",","") -> AK | N34: =B34 -> 71.3 | O34: =C34 -> 156.78
A35: [BTI] | B35: 70.13 | C35: 143.63 | D35: Barter | E35: Islan,AK | H35: Barter Islan,AK | J35: =LEFT(H35,LEN(H35)-5) -> Barter Isla | K35: =RIGHT(H35,4) -> ,AK | L35: =LEFT(K35,LEN(K35)-1) -> ,AK | M35: =SUBSTITUTE(L35,",","") -> AK | N35: =B35 -> 70.13 | O35: =C35 -> 143.63
A36: [BET] | B36: 60.78 | C36: 161.8 | D36: Bethel | E36: Arpt,AK | H36: Bethel Arpt,AK | J36: =LEFT(H36,LEN(H36)-5) -> Bethel Arp | K36: =RIGHT(H36,4) -> ,AK | L36: =LEFT(K36,LEN(K36)-1) -> ,AK | M36: =SUBSTITUTE(L36,",","") -> AK | N36: =B36 -> 60.78 | O36: =C36 -> 161.8
A37: [BTT] | B37: 66.92 | C37: 151.52 | D37: Bettles,AK | H37: Bettles,AK | J37: =LEFT(H37,LEN(H37)-5) -> Bettles | K37: =RIGHT(H37,4) -> AK | L37: =LEFT(K37,LEN(K37)-1) -> AK | M37: =SUBSTITUTE(L37,",","") -> AK | N37: =B37 -> 66.92 | O37: =C37 -> 151.52
A38: [BIG] | B38: 64 | C38: 145.73 | D38: Big | E38: Delta,AK | H38: Big Delta,AK | J38: =LEFT(H38,LEN(H38)-5) -> Big Delt | K38: =RIGHT(H38,4) -> ,AK | L38: =LEFT(K38,LEN(K38)-1) -> ,AK | M38: =SUBSTITUTE(L38,",","") -> AK | N38: =B38 -> 64 | O38: =C38 -> 145.73
A39: [5BI] | B39: 60.82 | C39: 152.3 | D39: Big | E39: River | F39: Lk,AK | H39: Big River Lk,AK | J39: =LEFT(H39,LEN(H39)-5) -> Big River | K39: =RIGHT(H39,4) -> k,AK | L39: =LEFT(K39,LEN(K39)-1) -> k,A | M39: =SUBSTITUTE(L39,",","") -> kA | N39: =B39 -> 60.82 | O39: =C39 -> 152.3
A40: [Z68] | B40: 63.38 | C40: 148.95 | D40: Cantwell,AK | H40: Cantwell,AK | J40: =LEFT(H40,LEN(H40)-5) -> Cantwell | K40: =RIGHT(H40,4) -> AK | L40: =LEFT(K40,LEN(K40)-1) -> AK | M40: =SUBSTITUTE(L40,",","") -> AK | N40: =B40 -> 63.38 | O40: =C40 -> 148.95
A41: [CDE] | B41: 56 | C41: 134.22 | D41: Cape | E41: Decis,AK | H41: Cape Decis,AK | J41: =LEFT(H41,LEN(H41)-5) -> Cape Deci | K41: =RIGHT(H41,4) -> ,AK | L41: =LEFT(K41,LEN(K41)-1) -> ,AK | M41: =SUBSTITUTE(L41,",","") -> AK | N41: =B41 -> 56 | O41: =C41 -> 134.22
A42: [5HN] | B42: 60.38 | C42: 147.08 | D42: Cape | E42: Hinchi,AK | H42: Cape Hinchi,AK | J42: =LEFT(H42,LEN(H42)-5) -> Cape Hinch | K42: =RIGHT(H42,4) -> ,AK | L42: =LEFT(K42,LEN(K42)-1) -> ,AK | M42: =SUBSTITUTE(L42,",","") -> AK | N42: =B42 -> 60.38 | O42: =C42 -> 147.08
A43: [CSP] | B43: 58.33 | C43: 137.05 | D43: Cape | E43: Spence,AK | H43: Cape Spence,AK | J43: =LEFT(H43,LEN(H43)-5) -> Cape Spenc | K43: =RIGHT(H43,4) -> ,AK | L43: =LEFT(K43,LEN(K43)-1) -> ,AK | M43: =SUBSTITUTE(L43,",","") -> AK | N43: =B43 -> 58.33 | O43: =C43 -> 137.05
A44: [5CE] | B44: 60.33 | C44: 145 | D44: Cape | E44: St | F44: Eli,AK | H44: Cape St Eli,AK | J44: =LEFT(H44,LEN(H44)-5) -> Cape St E | K44: =RIGHT(H44,4) -> i,AK | L44: =LEFT(K44,LEN(K44)-1) -> i,A | M44: =SUBSTITUTE(L44,",","") -> iA | N44: =B44 -> 60.33 | O44: =C44 -> 145
...
